Workbook

Sheet Rate Card
A1: ALD RATE CARD & ASSUMPTIONS · KAWASAKI MOTORS MANUFACTURING CORP., U.S.A.
A2: Blue text on yellow = input. Every assumption carries its basis in column D. Defaults come from rate_card.yaml; rows marked JOB OVERRIDE were set in the job file.
A4: PRICING ASSUMPTIONS
A5: Energy Rate | B5: 0.0787 | C5: $/kWh | D5: JOB OVERRIDE. ASSUMPTION: Missouri statewide average industrial retail price, 2024 annual, U.S. EIA Electric Sales, Revenue and Average Price, Table 4 (7.87 cents/kWh). Not Kawasaki's Evergy tariff or bill. Replace with the plant's 12 month bill rate when available.
A6: Operating Hours | B6: 8760 | C6: hrs/yr | D6: ALD default 24/7/365 when the shift schedule is not known. Savings scale down in proportion if the plant does not run 24/7.
A7: kW per CFM | B7: 0.2 | C7: kW/CFM | D7: ALD planning factor (DOE Sourcebook about 0.197 kW/CFM at 100 psi). On fixed speed machines saved CFM only becomes saved kW once a unit is turned off or load shifted.
A8: Materials / Service Margin Floor | B8: 0.2 | C8: % | D8: ALD minimum gross margin. Sell = Cost / (1 - margin).
A9: Travel / Expense Margin | B9: 0.1 | C9: % | D9: ALD standard on pass-through travel.
A10: Labor Margin (leak detection) | B10: 0.4 | C10: % | D10: Fairlife / Fresno survey pattern (40%).
A11: Repair Labor Margin | B11: 0.5 | C11: % | D11: Fairlife / Petoskey repair pattern (50%).
A12: Price rounding increment | B12: 250 | C12: $ | D12: Customer price rounded UP to the next $250.
A14: SYSTEM / SIZING INPUTS
A15: Expected leak share | B15: 0.3 | C15: % | D15: ALD LD quote rule: expected leaks = 30% of operating capacity. The survey replaces this estimate.
A16: Guaranteed repair share | B16: 0.3 | C16: % | D16: Petoskey pattern: guarantee 30% of leak load. CFM guarantee, never a leak count.
A17: Avg CFM per leak (planning) | B17: 3 | C17: CFM | D17: Lactalis tags ran 2-4 CFM each. Used only to size repair parts.
A18: Parts cost per leak | B18: 25 | C18: $/leak | D18: ALD default $25/leak (AMG). Petoskey used $5. Sized to the full expected leak load, so it carries cushion.
A20: SERVICE RATE CARD (ALD COST)
A21: Tier 1 Field Technician | B21: 1200 | C21: $/day | D21: Tier 1 field technician cost, weekday. Weekend is $1,800/day.
A22: Flight, roundtrip per person | B22: 1600 | C22: $/person | D22: ALD rate card round trip per person. Use the actual fare when booked.
A23: Per Diem per person | B23: 100 | C23: $/day | D23: ALD rate card.
A24: Hotel | B24: 250 | C24: $/night | D24: ALD rate card. Use the actual rate when booked.
A25: Rental Car (Enterprise, Corp Acct AQT962X) | B25: 800 | C25: $/week | D25: Enterprise, Corp Acct AQT962X, one car shared by the crew.
A26: Air sample (ISO 8573-1) cost | B26: 150 | C26: $ | D26: ISO 8573-1 air sample cost (LDL1 PM master template). Offered complimentary.
A28: DAYS
A29: Survey on-site days | B29: 5 | C29: days | D29: JOB OVERRIDE. ASSUMPTION: 5 on-site days per tech, 2 techs. Expected leak load 1,961 CFM at about 3 CFM per leak is roughly 650 leaks across a 1,900 HP plant.
A30: Report days | B30: 1 | C30: days | D30: Office day to build the leak workbook and summary.
A31: Repair on-site days | B31: 10 | C31: days | D31: JOB OVERRIDE. ASSUMPTION: 10 on-site repair days per tech, same trip as the survey. Per Dom 10/13/26.
A32: Travel days (in/out) | B32: 1 | C32: days | D32: One fly-in day (per diem and hotel night). Fly-out happens on the last work day.
A33: Technicians on site | B33: 2 | C33: techs | D33: Tier 1 techs on site for survey and repair.
A34: Weekend nights between survey and repair | B34: 4 | C34: nights | D34: JOB OVERRIDE. ASSUMPTION: techs stay on site over two weekends (survey to repair, and mid repair).
A36: COMPRESSOR INVENTORY AND SIZING · Helen King (CAM Technologies) email, 10/13/26
A37: Sullair TS-20, fixed speed | B37: 200 | C37: HP | D37: Per Helen King (CAM Technologies) email, 10/13/26.
A38: Ingersoll Rand R110i, fixed speed | B38: 150 | C38: HP | D38: Per Helen King (CAM Technologies) email, 10/13/26.
A39: Ingersoll Rand (model not given), fixed speed | B39: 200 | C39: HP | D39: Per Helen King (CAM Technologies) email, 10/13/26.
A40: Ingersoll Rand Ri160e, fixed speed | B40: 200 | C40: HP | D40: Per Helen King (CAM Technologies) email, 10/13/26.
A41: Ingersoll Rand Ri160e, fixed speed (second unit) | B41: 200 | C41: HP | D41: Per Helen King (CAM Technologies) email, 10/13/26.
A42: Ingersoll Rand (model not given), fixed speed (second unit) | B42: 200 | C42: HP | D42: Per Helen King (CAM Technologies) email, 10/13/26.
A43: Ingersoll Rand R110i, fixed speed (second unit) | B43: 150 | C43: HP | D43: Per Helen King (CAM Technologies) email, 10/13/26.
A44: Centac, centrifugal | B44: 600 | C44: HP | D44: CFM per HP of 4.3 is a planning factor and may differ for a centrifugal.
A45: Unlisted unit (blank bullet in the email list) | B45: 0 | C45: HP | D45: ASSUMPTION: 0 HP. Enter its HP if Helen confirms one.
...

Sheet Quote Builder
A1: ALD QUOTE COST ENGINE · INTERNAL, NOT THE CUSTOMER COPY
A3: Quote No. | C3: ALD-2026-1013-KM | F3: Date | G3: 46308
A4: Prepared For | C4: CAM Technologies (Helen King, Regional Sales Manager, Midwest) | F4: Valid Through | G4: =G3+30 -> 46338
A5: End Client | C5: Kawasaki Motors Manufacturing Corp., U.S.A. · 28147 US-71 BUS, Maryville, MO 64468 | F5: Prepared By | G5: Dominick Ruggeri
A8: Option | B8: Category | C8: Description | D8: Qty | E8: Unit | F8: Unit Cost ($) | G8: Target Margin % | H8: Unit Sell ($) | I8: Ext. Cost ($) | J8: Ext. Sell ($) | K8: Profit ($) | L8: Margin %
A9: 1 | B9: Leak Detection Labor | C9: Tier 1 techs: (techs x survey on-site days) + report days | D9: ='Rate Card'!$B$33*'Rate Card'!$B$29+'Rate Card'!$B$30 -> 11 | E9: day | F9: ='Rate Card'!$B$21 -> 1200 | G9: ='Rate Card'!$B$10 -> 0.4 | H9: =IFERROR(F9/(1-G9),0) -> 2000 | I9: =D9*F9 -> 13200 | J9: =D9*H9 -> 22000 | K9: =J9-I9 -> 8800 | L9: =IFERROR(K9/J9,0) -> 0.4
A10: 1 | B10: Air Sample | C10: Complimentary ISO 8573-1 air sample (cost absorbed, $0 sell) | D10: 1 | E10: ea | F10: ='Rate Card'!$B$26 -> 150 | G10: 0 | H10: 0 | I10: =D10*F10 -> 150 | J10: =D10*H10 -> 0 | K10: =J10-I10 -> -150 | L10: =IFERROR(K10/J10,0) -> 0
A11: 1 | B11: Travel | C11: Flight RT, per tech (Livermore to Kansas City, then drive) | D11: ='Rate Card'!$B$33 -> 2 | E11: ea | F11: ='Rate Card'!$B$22 -> 1600 | G11: ='Rate Card'!$B$9 -> 0.1 | H11: =IFERROR(F11/(1-G11),0) -> 1777.7778 | I11: =D11*F11 -> 3200 | J11: =D11*H11 -> 3555.5556 | K11: =J11-I11 -> 355.55556 | L11: =IFERROR(K11/J11,0) -> 0.1
A12: 1 | B12: Travel | C12: Hotel (techs x survey on-site days, arrive evening before) | D12: ='Rate Card'!$B$33*'Rate Card'!$B$29 -> 10 | E12: night | F12: ='Rate Card'!$B$24 -> 250 | G12: ='Rate Card'!$B$9 -> 0.1 | H12: =IFERROR(F12/(1-G12),0) -> 277.77778 | I12: =D12*F12 -> 2500 | J12: =D12*H12 -> 2777.7778 | K12: =J12-I12 -> 277.77778 | L12: =IFERROR(K12/J12,0) -> 0.1
A13: 1 | B13: Travel | C13: Per diem (techs x (on-site days + fly-in day)) | D13: ='Rate Card'!$B$33*('Rate Card'!$B$29+'Rate Card'!$B$32) -> 12 | E13: day | F13: ='Rate Card'!$B$23 -> 100 | G13: ='Rate Card'!$B$9 -> 0.1 | H13: =IFERROR(F13/(1-G13),0) -> 111.11111 | I13: =D13*F13 -> 1200 | J13: =D13*H13 -> 1333.3333 | K13: =J13-I13 -> 133.33333 | L13: =IFERROR(K13/J13,0) -> 0.1
A14: 1 | B14: Travel | C14: Rental car (Enterprise, one week, shared car) | D14: 1 | E14: wk | F14: ='Rate Card'!$B$25 -> 800 | G14: ='Rate Card'!$B$9 -> 0.1 | H14: =IFERROR(F14/(1-G14),0) -> 888.88889 | I14: =D14*F14 -> 800 | J14: =D14*H14 -> 888.88889 | K14: =J14-I14 -> 88.888889 | L14: =IFERROR(K14/J14,0) -> 0.1
A15: 2 | B15: Repair Labor | C15: Tier 1 techs: techs x repair on-site days | D15: ='Rate Card'!$B$33*'Rate Card'!$B$31 -> 20 | E15: day | F15: ='Rate Card'!$B$21 -> 1200 | G15: ='Rate Card'!$B$11 -> 0.5 | H15: =IFERROR(F15/(1-G15),0) -> 2400 | I15: =D15*F15 -> 24000 | J15: =D15*H15 -> 48000 | K15: =J15-I15 -> 24000 | L15: =IFERROR(K15/J15,0) -> 0.5
A16: 2 | B16: Parts | C16: Repair parts: est. leaks in full expected leak load (leak load CFM / avg CFM per leak) | D16: =ROUNDUP($C$30/'Rate Card'!$B$17,0) -> 654 | E16: leak | F16: ='Rate Card'!$B$18 -> 25 | G16: ='Rate Card'!$B$8 -> 0.2 | H16: =IFERROR(F16/(1-G16),0) -> 31.25 | I16: =D16*F16 -> 16350 | J16: =D16*H16 -> 20437.5 | K16: =J16-I16 -> 4087.5 | L16: =IFERROR(K16/J16,0) -> 0.2
A17: 2 | B17: Travel | C17: Added hotel nights (techs x (repair days + weekend nights), same trip) | D17: ='Rate Card'!$B$33*('Rate Card'!$B$31+'Rate Card'!$B$34) -> 28 | E17: night | F17: ='Rate Card'!$B$24 -> 250 | G17: ='Rate Card'!$B$9 -> 0.1 | H17: =IFERROR(F17/(1-G17),0) -> 277.77778 | I17: =D17*F17 -> 7000 | J17: =D17*H17 -> 7777.7778 | K17: =J17-I17 -> 777.77778 | L17: =IFERROR(K17/J17,0) -> 0.1
A18: 2 | B18: Travel | C18: Added per diem (techs x (repair days + weekend days)) | D18: ='Rate Card'!$B$33*('Rate Card'!$B$31+'Rate Card'!$B$34) -> 28 | E18: day | F18: ='Rate Card'!$B$23 -> 100 | G18: ='Rate Card'!$B$9 -> 0.1 | H18: =IFERROR(F18/(1-G18),0) -> 111.11111 | I18: =D18*F18 -> 2800 | J18: =D18*H18 -> 3111.1111 | K18: =J18-I18 -> 311.11111 | L18: =IFERROR(K18/J18,0) -> 0.1
A19: 2 | B19: Travel | C19: Added rental car (repair weeks beyond the survey week, same car) | D19: =ROUNDUP('Rate Card'!$B$31/5,0) -> 2 | E19: wk | F19: ='Rate Card'!$B$25 -> 800 | G19: ='Rate Card'!$B$9 -> 0.1 | H19: =IFERROR(F19/(1-G19),0) -> 888.88889 | I19: =D19*F19 -> 1600 | J19: =D19*H19 -> 1777.7778 | K19: =J19-I19 -> 177.77778 | L19: =IFERROR(K19/J19,0) -> 0.1
A22: OPTION TOTALS
A23: Option | B23: Ext. Cost ($) | C23: Ext. Sell (calc) | D23: CUSTOMER PRICE (rounded up) | E23: Profit ($) | F23: Margin % (on customer price) | G23: Floor check (>=floor)
A24: Survey | B24: =SUMIF($A$9:$A$19,1,$I$9:$I$19) -> 21050 | C24: =SUMIF($A$9:$A$19,1,$J$9:$J$19) -> 30555.556 | D24: =CEILING(C24,'Rate Card'!$B$12) -> 30750 | E24: =D24-B24 -> 9700 | F24: =IFERROR(E24/D24,0) -> 0.31544715 | G24: =IF(F24>='Rate Card'!$B$8,"OK","BELOW FLOOR") -> OK
A25: Repair add-on | B25: =SUMIF($A$9:$A$19,2,$I$9:$I$19) -> 51750 | C25: =SUMIF($A$9:$A$19,2,$J$9:$J$19) -> 81104.167 | D25: =CEILING(C25,'Rate Card'!$B$12) -> 81250 | E25: =D25-B25 -> 29500 | F25: =IFERROR(E25/D25,0) -> 0.36307692 | G25: =IF(F25>='Rate Card'!$B$8,"OK","BELOW FLOOR") -> OK
A26: Survey + repair add-on | B26: =B24+B25 -> 72800 | C26: =C24+C25 -> 111659.72 | D26: =D24+D25 -> 112000 | E26: =D26-B26 -> 39200 | F26: =IFERROR(E26/D26,0) -> 0.35 | G26: =IF(F26>='Rate Card'!$B$8,"OK","BELOW FLOOR") -> OK
A28: SAVINGS & ROI
A29: Sizing flow (CFM) | C29: ='Rate Card'!$B$52 -> 6536 | E29: Rate Card
A30: Expected leak load (CFM) | C30: =ROUND(C29*'Rate Card'!$B$15,0) -> 1961 | E30: Flow x leak share
A31: Leak load kWh/yr | C31: =C30*'Rate Card'!$B$7*'Rate Card'!$B$6 -> 3435672 | E31: CFM x kW/CFM x hrs
A32: Potential annual savings, full leak load ($) | C32: =C31*'Rate Card'!$B$5 -> 270387.39 | E32: kWh x rate
A33: Guaranteed CFM (repair add-on) | C33: =ROUND(C30*'Rate Card'!$B$16,0) -> 588 | E33: Leak load x guarantee share. ONE driver for the repair add-on.
A34: Guaranteed kW | C34: =C33*'Rate Card'!$B$7 -> 117.6
A35: Guaranteed bhp | C35: =C34/0.746 -> 157.64075 | E35: kW / 0.746
A36: Guaranteed kWh/yr | C36: =C34*'Rate Card'!$B$6 -> 1030176
A37: Guaranteed annual savings ($) | C37: =C36*'Rate Card'!$B$5 -> 81074.851
A38: Cost of delay, full leak load ($/month) | C38: =C32/12 -> 22532.282
A39: Survey payback on potential savings (months) | C39: =IFERROR($D$24/C32*12,0) -> 1.3647086
A40: Repair add-on payback on guaranteed savings (months) | C40: =IFERROR($D$25/C37*12,0) -> 12.025924
A41: Survey + repair add-on payback on guaranteed savings (months) | C41: =IFERROR($D$26/C37*12,0) -> 16.577274 | E41: Conservative: no credit for leaks found but not repaired
A42: Leak load bhp | C42: =C30*'Rate Card'!$B$7/0.746 -> 525.73727
A43: Leak load kW | C43: =C30*'Rate Card'!$B$7 -> 392.2
A45: MARGIN HEADROOM
A46: Price at the margin floor, survey + repair add-on | C46: =CEILING($B$26/(1-'Rate Card'!$B$8),'Rate Card'!$B$12) -> 91000
A47: Customer price above the floor | C47: =$D$26-C46 -> 21000
...
